Workbook

Sheet Read me
A1: Mini systematic review - screening log (Session 4 deliverable)
A2: Author: Mayte Ciriaco Ruiz | Course: Research Methods & Scientific Integrity in AI (UNMSM) | Search date: 24 October 2026
A4: HOW TO USE (yellow cells are yours to fill; everything else is formula or fixed)
A5: 1. Screening was done by the AI (columns I/J of 'Screening (human)' are AI-proposed). You only validate the 6 records marked Y in column T: read the abstract and write Agree or Disagree in column U (if Disagree, change I/J yourself).
A6: Example: U5 = Agree.
A7: 2. Sheet 'Validation' counts your checks and the 10% rule. 'AI screening' keeps the rationale for every record.
A8: 3. Full text: for records you carried forward, fill K (Eligible / Exclude / Not retrieved) and L (reason code), plus M (Tier 1/2), N, O (Y/N) for the tie-break.
A9: 4. Column P/Q rank the eligible papers by the dated tie-break rule (tier, then Spanish/LatAm/low-resource context, then traceability/governance, then year). Mark the top 10 as Yes in R; the rest as No (they become E9 automatically).
A10: 5. Sheet 'PRISMA numbers' fills itself. Type those numbers into the official PRISMA 2020 app. The 'Checks' block must say OK everywhere.
A12: AI USE DECLARATION
A13: An AI assistant (Claude, Anthropic; claude.ai; 24 Oct 2026) was the primary screener: it applied the dated criteria v1.0 to the title, abstract and author keywords of all 44 records and proposed a decision and reason code for each (sheet 'AI screening'). The human reviewer validated a random sample (5 records, seed 20261024) plus one low-confidence record, i.e. more than 10% of records, and resolved disagreements. Full-text eligibility and the final selection of 10 were done by the human reviewer. Agreement on the sample is reported in sheet 'Validation'.
A14: The prompt/instructions given to the AI were: the criteria in sheet 'Criteria v1.0' (I1-I6, tiers, tie-break, reason codes E1-E9), applied to the title, abstract and author keywords exported from Scopus.
... A23: Because of the delivery deadline, full texts were assessed in the fixed order shown in sheet 'Reading order' instead of assessing all records carried forward. Records eligible by abstract but not reached are reported as E9 (not assessed) at the screening stage in PRISMA. This limits the selection of the final 10 to the highest-priority records and is reported as a limitation.

Sheet Search log
A1: Iteration | B1: Database | C1: Date searched | D1: Blocks | E1: Filters | F1: n (records) | G1: Full search string
A2: 1 | B2: Scopus | C2: 2026-10-24 | D2: Multi-agent + extraction/verification + public documents + Spanish/Peru/LatAm | E2: 2020-2026; article | F2: 0 | G2: TITLE-ABS-KEY(("multi-agent" OR "multi-agent system*" OR "LLM agent*") AND ("information extraction" OR "document verification" OR "fact-checking" OR "fact verification" OR "claim verification") AND ("public document*" OR "government document*" OR "administrative document*" OR "legal document*" OR "civic") AND (Spanish OR "low-resource language*" OR Peru OR "Latin America")) AND PUBYEAR > 2019 AND PUBYEAR < 2027 AND DOCTYPE(ar)
A3: 2 | B3: Scopus | C3: 2026-10-24 | D3: Multi-agent + extraction/verification | E3: 2020-2026; article | F3: 72 | G3: TITLE-ABS-KEY(("multi-agent" OR "multi-agent system*" OR "LLM agent*") AND ("information extraction" OR "document verification" OR "fact-checking" OR "fact verification" OR "claim verification")) AND PUBYEAR > 2019 AND PUBYEAR < 2027 AND DOCTYPE(ar)
A4: 3 | B4: Scopus | C4: 2026-10-24 | D4: Multi-agent + LLM + extraction/verification (FINAL) | E4: 2020-2026; article; journal sources | F4: 44 | G4: TITLE-ABS-KEY(("multi-agent" OR "multi-agent system*" OR "LLM agent*") AND ("large language model*" OR LLM OR LLMs) AND ("information extraction" OR "document verification" OR "fact-checking" OR "fact verification" OR "claim verification")) AND PUBYEAR > 2019 AND PUBYEAR < 2027 AND DOCTYPE(ar) AND SRCTYPE(j)
A6: Note: Spanish, Peru/LatAm and document type were NOT used as search filters; they are applied as criteria/tie-break during screening (iteration 1 returned 0). n values were read from the Scopus results screen on the search date.

Sheet Criteria v1.0
A1: Inclusion criteria (all must be met)
A2: I1 | B2: Peer-reviewed journal article (Scopus DOCTYPE ar, SRCTYPE j), published 2020-2026, with a DOI.
A3: I2 | B3: Full text in English or Spanish and accessible to the reviewer.
A4: I3 | B4: Uses large language models as a core component.
A5: I4 | B5: Uses a multi-agent architecture (two or more interacting agents with distinct roles), not a single-model pipeline.
A6: I5 | B6: Addresses at least one of: information extraction, classification, or verification (fact, claim or document verification).
A7: I6 | B7: Operates on unstructured text documents or claims (not images, sensors, or tabular data only).
A8: Priority tiers (applied after I1-I6)
A9: Tier 1 | B9: Applied to public, government, administrative, legal or civic documents.
A10: Tier 2 | B10: Applied to other unstructured text (e.g., news, scientific text) in any language.
A11: Tie-break (in order) | B11: (1) tier; (2) Spanish, Latin American or low-resource-language context; (3) explicit treatment of traceability, provenance or ethical governance; (4) most recent year.
A12: Exclusion reason codes (one per record)
A13: E1 | B13: Not a journal article or no DOI
A14: E2 | B14: Language not English/Spanish
A15: E3 | B15: Not LLM-based
A16: E4 | B16: Not multi-agent
A17: E5 | B17: No extraction, classification or verification task
A18: E6 | B18: Out of domain (non-text data or unrelated application)
A19: E7 | B19: Full text not retrievable
A20: E8 | B20: Duplicate record
A21: E9 | B21: Eligible but not selected (below the 10-article cut by tie-break rule)
A22: Version | B22: v1.0, dated 24 October 2026, written before screening decisions.

Sheet Screening (human)
A1: ID | B1: First author | C1: Year | D1: Title | E1: Source | F1: DOI | G1: Language | H1: Abstract (Scopus) | I1: Title/abstract decision (AI-proposed; human validation in col T/U) | J1: Reason code (if Exclude) | K1: Full-text decision (Eligible / Exclude / Not retrieved) | L1: Full-text reason code | M1: Tier (1 or 2) | N1: Spanish/LatAm/low-resource context (Y/N) | O1: Traceability/governance explicit (Y/N) | P1: Priority score (auto) | Q1: Rank (auto) | R1: Selected in top 10 (Yes / No) | S1: Final status (auto) | T1: In validation sample (Y) | U1: Human check: Agree / Disagree | V1: Not assessed at full text: eligible by abstract, below prioritised-reading cut (Y = E9)
A2: 1 | B2: Zhou X. | C2: 2026 | D2: Research on solid-state battery information mining based on large language models and chain-of-thought reasoning | E2: Journal of Energy Storage | F2: 10.1016/j.est.2026.125065 | G2: English | H2: Solid-state batteries (SSBs) represent a next-generation energy storage technology. However, the wide diversity of solid-state electrolyte (SSE) chemistries, coupled with the complexity of their synthesis and processing routes, makes systematic investigation, knowledge reuse, and database construction particularly challenging. In this work, we propose SSBExtractor, a novel information extraction framework designed to mine synthesis protocols and performance metrics from scientific literature using large language models (LLMs) enhanced with chain-of-thought (CoT) reasoning. Unlike conventional rule-based or direct prompting methods, SSBExtractor decomposes the extraction task into four structured stages, localization, extraction, matching, and formatting, with each stage utilizing a corresponding dedicated prompt. We further introduce a multi-agent interactive prompt refinement approach to improve extraction accuracy through iterative feedback from labeled data and domain experts. Applied to a dataset of 800 SSB-related papers, SSBExtractor successfully established the largest SSE synthesis-process database to date, covering 851 electrolyte materials and 15,337 process parameters. Relying on CoT-based framework rather than resource-intensive fine-tuning, the proposed framework achieved over 98.5% precision and recall, significantly outperforming standard prompting methods. Notably, the CoT-based framework proved particularly effective in handling complex cases involving multiple materials and synthesis routes within a single article, where traditional methods often failed. This work demonstrates the potential of CoT reasoning in LLMs for accurate, scalable scientific information extraction and offers a foundational methodology with prospective applicability for knowledge mining across broader materials science domains. © 2026 Elsevier Ltd. All rights are reserved, including those for text and data mining, AI training, and similar technologies. | I2: Maybe | P2: =IF(K2="Eligible",IF(M2=1,1000,0)+IF(N2="Y",100,0)+IF(O2="Y",10,0)+(C2-2019)/10,"") | Q2: =IF(P2="","",RANK(P2,$P$2:$P$45)) | S2: =IF(I2="","Pending",IF(I2="Exclude","Excluded at title/abstract",IF(V2="Y","Excluded: eligible by abstract, not assessed (E9)",IF(K2="","Pending full text",IF(K2="Exclude","Excluded at full text",IF(K2="Not retrieved","Not retrieved",IF(R2="Yes","Included",IF(R2="No","Excluded: eligible, not selected (E9)","Eligible - pending selection")))))))) -> Pending full text
A3: 2 | B3: Gorshenin A.K. | C3: 2025 | D3: A Multiagent Multimodal Neural Architecture with Probabilistic Evidence Aggregation for Detecting Fake Messages | E3: Pattern Recognition and Image Analysis | F3: 10.1134/S1054661825700543 | G3: English | H3: Abstract: This paper presents a new multiagent architecture with probabilistic data aggregation for detecting fake messages in text, images, and audio sources. The development of such approaches is increasingly in demand for a variety of information systems due to the growing volume of heterogeneous content, the limitations of single models in credibility assessment, and the lack of sufficiently large labeled datasets in real-world conditions that would allow the effective detection of unreliable content, which leads to the need to use probabilistic approaches. The fundamental novelty of the solution presented in this work lies in the probabilistic aggregation of agent inferences with confidence calibration and interpretable justifications. The architecture includes an intelligent router, modality-specific agents, and a context-weighted aggregation module. To evaluate the quality of the proposed architecture and compare it with various large language models, a custom graph dataset of real and synthetic messages with various combinations of modalities was created. In the experimental series, the aggregator outperformed single text (Mistral-7B-Instruct-v0.3, Phi-4, etc.) and vision language models (for example, LLaVa‑v1.5‑7B and Qwen2‑vl‑2B‑Instruct, etc.): the values of the accuracy metrics (Accuracy) and F1-score of the proposed architecture are 10–17% higher; the Weighted F1‑score values improved by 16%; the values of the Brier score and log loss metrics, reflecting the calibration of probabilistic predictions and the severity of penalty for overconfident errors, were reduced by 13–30%. The system operates in zero-shot mode based on open pretrained models, including YandexGPT‑5‑Lite‑8B‑Instruct, Qwen3‑8B and those vision language models mentioned above, and supports fast domain adaptation using system prompts and standardized output formats. The results demonstrate the effectiveness of the multiagent approach for reliable assessment of the credibility of multimodal messages and its applicability to intelligent content quality control tools in modern general-purpose information systems, including social networks. © Pleiades Publishing, Ltd. 2025. | I3: Include | P3: =IF(K3="Eligible",IF(M3=1,1000,0)+IF(N3="Y",100,0)+IF(O3="Y",10,0)+(C3-2019)/10,"") | Q3: =IF(P3="","",RANK(P3,$P$2:$P$45)) | S3: =IF(I3="","Pending",IF(I3="Exclude","Excluded at title/abstract",IF(V3="Y","Excluded: eligible by abstract, not assessed (E9)",IF(K3="","Pending full text",IF(K3="Exclude","Excluded at full text",IF(K3="Not retrieved","Not retrieved",IF(R3="Yes","Included",IF(R3="No","Excluded: eligible, not selected (E9)","Eligible - pending selection")))))))) -> Pending full text
A4: 3 | B4: Alghamdi H.M. | C4: 2024 | D4: Towards Reliable Healthcare LLM Agents: A Case Study for Pilgrims during Hajj | E4: Information (Switzerland) | F4: 10.3390/info15070371 | G4: English | H4: There is a pressing need for healthcare conversational agents with domain-specific expertise to ensure the provision of accurate and reliable information tailored to specific medical contexts. Moreover, there is a notable gap in research ensuring the credibility and trustworthiness of the information provided by these healthcare agents, particularly in critical scenarios such as medical emergencies. Pilgrims come from diverse cultural and linguistic backgrounds, often facing difficulties in accessing medical advice and information. Establishing an AI-powered multilingual chatbot can bridge this gap by providing readily available medical guidance and support, contributing to the well-being and safety of pilgrims. In this paper, we present a comprehensive methodology aimed at enhancing the reliability and efficacy of healthcare conversational agents, with a specific focus on addressing the needs of Hajj pilgrims. Our approach leverages domain-specific fine-tuning techniques on a large language model, alongside synthetic data augmentation strategies, to optimize performance in delivering contextually relevant healthcare information by introducing the HajjHealthQA dataset. Additionally, we employ a retrieval-augmented generation (RAG) module as a crucial component to validate uncertain generated responses, which improves model performance by 5%. Moreover, we train a secondary AI agent on a well-known health fact-checking dataset and use it to validate medical information in the generated responses. Our approach significantly elevates the chatbot’s accuracy, demonstrating its adaptability to a wide range of pilgrim queries. We evaluate the chatbot’s performance using quantitative and qualitative metrics, highlighting its proficiency in generating accurate responses and achieve competitive results compared to state-of-the-art models, in addition to mitigating the risk of misinformation and providing users with trustworthy health information. © 2024 by the authors. | I4: Maybe | P4: =IF(K4="Eligible",IF(M4=1,1000,0)+IF(N4="Y",100,0)+IF(O4="Y",10,0)+(C4-2019)/10,"") | Q4: =IF(P4="","",RANK(P4,$P$2:$P$45)) | S4: =IF(I4="","Pending",IF(I4="Exclude","Excluded at title/abstract",IF(V4="Y","Excluded: eligible by abstract, not assessed (E9)",IF(K4="","Pending full text",IF(K4="Exclude","Excluded at full text",IF(K4="Not retrieved","Not retrieved",IF(R4="Yes","Included",IF(R4="No","Excluded: eligible, not selected (E9)","Eligible - pending selection")))))))) -> Pending full text
A5: 4 | B5: Pu J. | C5: 2026 | D5: MA-APKG: A multi-agent LLM-based method for construction aviation product assembly process knowledge graph | E5: Journal of Manufacturing Systems | F5: 10.1016/j.jmsy.2026.04.031 | G5: English | H5: To address the characteristics of complex aviation assembly process knowledge, including diverse knowledge types, complex hierarchical structures, strong semantic correlations, and continuous evolution, a top-down construction method for an assembly process knowledge graph (KG) is proposed. First, a multi-level assembly process ontology is developed to provide unified and standardized modeling of product information, assembly process knowledge, tools and equipment, historical cases, and their cross-level relationships, enabling structured knowledge representation and semantic consistency enforcement. Second, to cope with the semantic complexity of assembly process texts, a large language model (LLM)-based multi-agent collaborative triple information extraction method is proposed. By integrating ontology constraints and a self-consistency chain-of-thought (CoT) mechanism, the stability, accuracy, and interpretability of extraction results are significantly improved. Finally, a semantic embedding-based dynamic KG update strategy is adopted to maintain entity uniqueness and semantic consistency during continuous knowledge evolution. Experimental results demonstrate the effectiveness and applicability of the proposed method in complex aviation assembly process scenarios. © 2026 The Society of Manufacturing Engineers | I5: Include | P5: =IF(K5="Eligible",IF(M5=1,1000,0)+IF(N5="Y",100,0)+IF(O5="Y",10,0)+(C5-2019)/10,"") | Q5: =IF(P5="","",RANK(P5,$P$2:$P$45)) | S5: =IF(I5="","Pending",IF(I5="Exclude","Excluded at title/abstract",IF(V5="Y","Excluded: eligible by abstract, not assessed (E9)",IF(K5="","Pending full text",IF(K5="Exclude","Excluded at full text",IF(K5="Not retrieved","Not retrieved",IF(R5="Yes","Included",IF(R5="No","Excluded: eligible, not selected (E9)","Eligible - pending selection")))))))) -> Pending full text
A6: 5 | B6: Lian X. | C6: 2026 | D6: An LLM-based Fact-Checking Approach for Multilingual Fake News Detection in Short-Form Video News | E6: Information Systems Frontiers | F6: 10.1007/s10796-026-10755-x | G6: English | H6: Fake news increasingly spans multiple languages and modalities, especially on short-form video platforms, making detection more complex. This paper introduces the first study addressing multilingual fake news detection for content that incorporates multiple languages within a single news item. This study utilizes the Design Science Research (DSR) paradigm and presents an automated large language model (LLM)-based fact-checking approach for multilingual fake news detection that requires no extensive task-specific training data. Our method includes: (1) LLM-based cross-modal consistency filtering to identify discrepancies across modalities; and (2) LLM-based fact verification implemented through a multi-agent system. We evaluated our approach using an existing multilingual text fake news dataset and a novel multilingual short-form video fake news dataset (MSVFD). Experimental results show our approach outperforms leading supervised and LLM-based prompting methods. This research addresses a critical gap in multilingual fake news literature and contributes to DSR on LLM-based artifacts, highlighting their potential for timely misinformation detection across diverse formats and languages. © The Author(s), under exclusive licence to Springer Science+Business Media, LLC, part of Springer Nature 2026. | I6: Include | P6: =IF(K6="Eligible",IF(M6=1,1000,0)+IF(N6="Y",100,0)+IF(O6="Y",10,0)+(C6-2019)/10,"") | Q6: =IF(P6="","",RANK(P6,$P$2:$P$45)) | S6: =IF(I6="","Pending",IF(I6="Exclude","Excluded at title/abstract",IF(V6="Y","Excluded: eligible by abstract, not assessed (E9)",IF(K6="","Pending full text",IF(K6="Exclude","Excluded at full text",IF(K6="Not retrieved","Not retrieved",IF(R6="Yes","Included",IF(R6="No","Excluded: eligible, not selected (E9)","Eligible - pending selection")))))))) -> Pending full text | T6: Y
A7: 6 | B7: Menotti L. | C7: 2025 | D7: Provenance-driven nanopublications: representing source lineage and trust networks for multi-source assertions | E7: International Journal on Digital Libraries | F7: 10.1007/s00799-025-00431-x | G7: English | H7: Nanopublishing is a paradigm enabling the representation of scientific claims in a distinctive, identifiable, citable, and reusable format, i.e., as a named graph. This approach can be applied to sentences extracted from scientific publications or triples within a Knowledge Base (KB). This way, one can track the provenance of assertions derived from a specific publication or database. However, nanopublications do not natively support multi-source scientific claims generated by aggregating different bodies of knowledge. This work extends the nanopublication model with knowledge provenance, capturing provenance information for assertions derived by an aggregation algorithm or a truth discovery process, e.g., an information extraction system aggregating several sources of knowledge to populate a Knowledge Base (KB). In these cases, provenance information cannot be attributed to a single source, but it is the result of an ensemble of evidence, that can comprehend supporting and conflicting pieces of evidence and truth values. Knowledge provenance is represented as a named graph following the PROV-K ontology, developed for the case. To show how knowledge provenance applies to a real-world scenario, we serialized gene expression-cancer associations generated by the Collaborative Oriented Relation Extraction (CORE) System. To demonstrate the value of trust relationships, we present a use case leveraging an existing scientific KB to construct a trust network employing three Large Language Model (LLM) agents. We analyzed the ability of LLMs to evaluate trustworthiness, exploiting techniques from KB accuracy estimation. We published 197, 511 assertions generated by the CORE system in the form of extended nanopublications with knowledge provenance. PROV-K also defines trust relationships between agents or between an agent and a proposition. Starting from these assertions, we leveraged external agents – namely, multiple LLMs – to assess their trusted truth value. Based on these values, we defined trust relationships between the agents and the facts, yielding an exemplar trust network comprising over 45,000 facts and four agents. The knowledge provenance graph allows the tracking of provenance for each piece of evidence contributing to the support or refutation of an assertion. To capture the semantics of the newly presented graph, we define the PROV-K ontology, designed to represent provenance information for multi-source assertions. The two use cases serve as a template to show how to serialize extended nanopublications and showcase the trust relationships’ capabilities. © The Author(s) 2025. | I7: Exclude | J7: E3 | P7: =IF(K7="Eligible",IF(M7=1,1000,0)+IF(N7="Y",100,0)+IF(O7="Y",10,0)+(C7-2019)/10,"") | Q7: =IF(P7="","",RANK(P7,$P$2:$P$45)) | S7: =IF(I7="","Pending",IF(I7="Exclude","Excluded at title/abstract",IF(V7="Y","Excluded: eligible by abstract, not assessed (E9)",IF(K7="","Pending full text",IF(K7="Exclude","Excluded at full text",IF(K7="Not retrieved","Not retrieved",IF(R7="Yes","Included",IF(R7="No","Excluded: eligible, not selected (E9)","Eligible - pending selection")))))))) -> Excluded at title/abstract
A8: 7 | B8: Gebreab S. | C8: 2026 | D8: An LLM-based multi-agent system for patient discharge assessment | E8: Computer Methods and Programs in Biomedicine Update | F8: 10.1016/j.cmpbup.2026.100261 | G8: English | H8: Hospital discharge planning plays a central role in patient flow, quality of care, and hospital efficiency. However, discharge assessment is often fragmented across teams and performed under tight time constraints. Existing machine-learning models trained on electronic health record (EHR) data have been applied to forecast near-term discharge events, but they primarily estimate timing or probability and provide limited structured clinical interpretability. To address these limitations, we propose an LLM-based multi-agent clinical decision support system for discharge readiness assessment. The architecture decomposes discharge reasoning into five clinically distinct specialist agents, each producing structured, evidence-linked claims grounded in specific EHR fields. A deterministic, schema-based claim verification layer cross-checks the asserted field values against the patient record prior to arbitration, and a reliability-aware arbiter synthesizes verified assessments into a final readiness determination. This design replaces a single scalar score with multidimensional, auditable reasoning while explicitly separating generative reasoning from value-level data checking. Evaluated on a retrospective MIMIC-IV cohort across four LLM backbones, binary prediction of proxy safe early discharge under the SAFE_D24 definition ranged from 0.490 to 0.620 F1, with PPV from 0.521 to 0.628. GPT-4.1 achieved the strongest performance (0.620 F1, 75.8% specificity, 61.3% sensitivity). Ablation analysis demonstrates measurable performance gains from deterministic verification. Beyond discrimination metrics, the system produces traceable barrier identification, claim-level verification statistics, and configurable human-review triggers, supporting traceable and auditable discharge assessment with explicit safety and operational trade-offs. © 2026 The Author(s) | I8: Maybe | P8: =IF(K8="Eligible",IF(M8=1,1000,0)+IF(N8="Y",100,0)+IF(O8="Y",10,0)+(C8-2019)/10,"") | Q8: =IF(P8="","",RANK(P8,$P$2:$P$45)) | S8: =IF(I8="","Pending",IF(I8="Exclude","Excluded at title/abstract",IF(V8="Y","Excluded: eligible by abstract, not assessed (E9)",IF(K8="","Pending full text",IF(K8="Exclude","Excluded at full text",IF(K8="Not retrieved","Not retrieved",IF(R8="Yes","Included",IF(R8="No","Excluded: eligible, not selected (E9)","Eligible - pending selection")))))))) -> Pending full text
A9: 8 | B9: Rahman S.S. | C9: 2026 | D9: Hallucination to truth: a review of fact-checking and factuality evaluation in large language models | E9: Artificial Intelligence Review | F9: 10.1007/s10462-025-11454-w | G9: English | H9: Large language models (LLMs) are trained on vast and diverse internet corpora that often include inaccurate or misleading content. Consequently, LLMs can generate misinformation, making robust fact-checking essential. This review systematically analyzes how LLM-generated content is evaluated for factual accuracy by exploring key challenges such as hallucinations, dataset limitations, and the reliability of evaluation metrics. The review emphasizes the need for strong fact-checking frameworks that integrate advanced prompting strategies, domain-specific fine-tuning, and retrieval-augmented generation (RAG) methods. It proposes five research questions that guide the analysis of the recent literature from 2020 to 2025, focusing on evaluation methods and mitigation techniques. Instruction tuning, multi-agent reasoning, and RAG frameworks for external knowledge access are also reviewed. The key findings demonstrate the limitations of current metrics, the importance of validated external evidence, and the improvement of factual consistency through domain-specific customization. The review underscores the importance of building more accurate, understandable, and context-aware fact-checking. These insights contribute to the advancement of research toward more trustworthy models. © The Author(s) 2026. | I9: Exclude | J9: E4 | P9: =IF(K9="Eligible",IF(M9=1,1000,0)+IF(N9="Y",100,0)+IF(O9="Y",10,0)+(C9-2019)/10,"") | Q9: =IF(P9="","",RANK(P9,$P$2:$P$45)) | S9: =IF(I9="","Pending",IF(I9="Exclude","Excluded at title/abstract",IF(V9="Y","Excluded: eligible by abstract, not assessed (E9)",IF(K9="","Pending full text",IF(K9="Exclude","Excluded at full text",IF(K9="Not retrieved","Not retrieved",IF(R9="Yes","Included",IF(R9="No","Excluded: eligible, not selected (E9)","Eligible - pending selection")))))))) -> Excluded at title/abstract
A10: 9 | B10: Zhang S. | C10: 2026 | D10: FARM: A Multi-Agent Framework for Automated Construction of Multi-Species Livestock Health Knowledge Graphs | E10: Agriculture (Switzerland) | F10: 10.3390/agriculture16030356 | G10: English | H10: Livestock health knowledge graphs are essential for decision-making and reasoning in animal husbandry, yet existing knowledge is scattered across unstructured literature and encoded in narrowly scoped, species-specific models, resulting in semantic fragmentation and limited reusability. To address these issues, we proposed FARM (Four-dimensional Automated-Reasoning Multi-agent), a zero-shot multi-agent framework used for constructing multi-species livestock health knowledge graphs. FARM is grounded in a Four-Dimension Livestock Health Framework encompassing Rearing Environment, Physiological Status, Feed & Water Inputs, and Production Performance, and employs a unified ontology strategy that integrates cross-species general labels with species-specific constraints to achieve semantic alignment. The framework orchestrates five specialized agents—Coordination, Entity Extraction, Ontology Normalization, Relation Extraction, and Knowledge Fusion—to automate the construction process. Experiments on 2478 expertly annotated text samples demonstrate that FARM achieves an entity-level F1 score of 0.8070 (IoU ≥ 0.5), surpassing the strongest baseline by 0.1627. Moreover, it attains a corrected entity label accuracy of 90.44% and an F1 score of 0.9277 in relation existence identification, outperforming the baseline by 0.1114. Validation on 500 image samples further confirms its capability in multimodal evidence fusion. The resulting knowledge graph contains 29,064 entities and 26,662 triples, providing a reusable foundation for zero-shot extraction and unified cross-species semantic modeling. © 2026 by the authors. | I10: Include | P10: =IF(K10="Eligible",IF(M10=1,1000,0)+IF(N10="Y",100,0)+IF(O10="Y",10,0)+(C10-2019)/10,"") | Q10: =IF(P10="","",RANK(P10,$P$2:$P$45)) | S10: =IF(I10="","Pending",IF(I10="Exclude","Excluded at title/abstract",IF(V10="Y","Excluded: eligible by abstract, not assessed (E9)",IF(K10="","Pending full text",IF(K10="Exclude","Excluded at full text",IF(K10="Not retrieved","Not retrieved",IF(R10="Yes","Included",IF(R10="No","Excluded: eligible, not selected (E9)","Eligible - pending selection")))))))) -> Pending full text
A11: 10 | B11: Cheng K. | C11: 2026 | D11: Insider Threat Detection and Evidence-Grounded Triage Using a Heterogeneous Dual-Branch Network and a Constrained LLM Agent | E11: Applied Sciences (Switzerland) | F11: 10.3390/app16147054 | G11: English | H11: Insider threats are difficult to detect and investigate because risky behavior can occur through valid accounts, develop slowly, and leave mixed behavioral traces. We study an analyst support architecture that links anomaly detection with evidence-based triage. Rather than treating insider threat analysis as a single classification task, the architecture organizes it as a workflow that combines behavior modeling, evidence retrieval, rule interpretation, and constrained reasoning. For anomaly detection, we build a multi-view representation over subject time windows and design a heterogeneous dual-branch network (HDBN) that fuses semantic and statistical branches through confidence-gated fusion. The detector captures temporal event patterns and statistical deviations while retaining structured alert clues for downstream investigation. For investigation, we construct a dual-track evidence infrastructure for LLM-assisted reasoning: a star schema data mart supports structured fact verification and a rule tree index supports policy and rule interpretation. An intent-aware hybrid retrieval mechanism routes sub-questions to the relevant evidence source and aligns structured facts with unstructured rules. We also design a constrained reasoning agent based on a controlled reasoning and acting workflow. Action-space constraints, evidence-completeness gating, and state recovery are used to limit reasoning drift and unsupported decisions when enterprise evidence is incomplete. On the CERT r4.2 dataset, the HDBN reaches 96.8% recall at the selected operating point. In the constructed investigation tasks, the constrained ReAct agent reaches 91.8% end-to-end triage accuracy compared to an unconstrained LLM agent baseline under the same tool access setting. The results support the feasibility of traceable detection-to-investigation workflows in the evaluated benchmark setting, while deployment on real enterprise data and adversarial scenarios remains to be validated. © 2026 by the authors. | I11: Exclude | J11: E4 | P11: =IF(K11="Eligible",IF(M11=1,1000,0)+IF(N11="Y",100,0)+IF(O11="Y",10,0)+(C11-2019)/10,"") | Q11: =IF(P11="","",RANK(P11,$P$2:$P$45)) | S11: =IF(I11="","Pending",IF(I11="Exclude","Excluded at title/abstract",IF(V11="Y","Excluded: eligible by abstract, not assessed (E9)",IF(K11="","Pending full text",IF(K11="Exclude","Excluded at full text",IF(K11="Not retrieved","Not retrieved",IF(R11="Yes","Included",IF(R11="No","Excluded: eligible, not selected (E9)","Eligible - pending selection")))))))) -> Excluded at title/abstract
A12: 11 | B12: Zhang W. | C12: 2026 | D12: An automatic modeling method for rough discrete fracture networks based on LLM Agent; [基于LLM Agent的粗糙离散裂隙网络自动建模方法] | E12: Scientia Sinica Technologica | F12: 10.1360/SST-2025-0414 | G12: Chinese | H12: Traditional rough discrete fracture network (RDFN) modeling relies on manual intervention, which is time-consuming and difficult to modify. To address this challenge, this study proposes an automatic RDFN modeling method based on a large language model agent (LLM Agent). The automatic parsing of modeling data by the LLM Agent and the potential issues of error propagation and objective drift during its reasoning process are the two major problems. Therefore, an automated fracture borehole wall profile extraction model is developed by improving YOLOv10 with an efficient multi-scale attention module, which is combined with fractal analysis to quantify fracture roughness. Additionally, an automatic fracture information extraction approach for CAD sketch, combined with Canny edge detection and GLM-4.1V-Thinking visual language model, is established for parameter extraction, including fracture length, fracture orientation, dip direction, and dip angle. With the above methods, the subjectivity and inefficiency of manual multi-source data extraction can be overcome. Furthermore, an LLM Agent’s autonomous reasoning method, based on prompt engineering and chain-of-thought reasoning, is proposed under the Reason+Act (ReAct) framework. This approach enables autonomous planning, reasoning, and error correction under the “action-feedback” closed-loop framework. Additionally, an automatic modeling system for rough discrete fracture networks has been developed, which enables full-process automation of modeling and modification, encompassing data analysis, parameter calculation, model construction, and verification. The proposed method is applied to a large-scale hydropower project in Southwest China. Based on acquired borehole images and CAD sketches of fracture outcrop observations, the LLM Agent automatically constructs an RDFN model for a 20 m×20 m×20 m volume, with an average time consumption of 8 min and 40 s, which significantly enhances the efficiency of fracture modeling. This study establishes a new paradigm for RDFN modeling. © 2026 Science Press. All rights reserved. | I12: Exclude | J12: E2 | P12: =IF(K12="Eligible",IF(M12=1,1000,0)+IF(N12="Y",100,0)+IF(O12="Y",10,0)+(C12-2019)/10,"") | Q12: =IF(P12="","",RANK(P12,$P$2:$P$45)) | S12: =IF(I12="","Pending",IF(I12="Exclude","Excluded at title/abstract",IF(V12="Y","Excluded: eligible by abstract, not assessed (E9)",IF(K12="","Pending full text",IF(K12="Exclude","Excluded at full text",IF(K12="Not retrieved","Not retrieved",IF(R12="Yes","Included",IF(R12="No","Excluded: eligible, not selected (E9)","Eligible - pending selection")))))))) -> Excluded at title/abstract
A13: 12 | B13: Zhou L. | C13: 2025 | D13: Semantic Information Extraction and Multi-Agent Communication Optimization Based on Generative Pre-Trained Transformer | E13: IEEE Transactions on Cognitive Communications and Networking | F13: 10.1109/TCCN.2024.3482354 | G13: English | H13: The collaboration among multiple agents demands for efficient communication. However, the observational data in the multi-agent systems are typically voluminous and redundant and pose substantial challenges to the communication system when transmitted directly. To address this issue, this paper introduces a multi-agent communication scheme based on large language model (LLM), referred to as GPT-based semantic information extraction for multi-agent communication (GMAC). This scheme utilizes an LLM to extract semantic information and leverages the generative capabilities to predict subsequent actions, thereby enabling agents to make more informed decisions. The GMAC approach significantly reduces signaling expenditure exchanged among agents by extracting key semantic data via LLM. This method not only simplifies the communication process but also effectively reduces the communication overhead by approximately 53% compared to the baseline methods. Experimental results indicate that GMAC not only improves the convergence speed and accuracy of decision-making but also substantially decreases the signaling expenditure among agents. Consequently, GMAC offers a straightforward and effective method to achieve efficient and economical communication in the multi-agent systems. © 2015 IEEE. | I13: Exclude | J13: E6 | P13: =IF(K13="Eligible",IF(M13=1,1000,0)+IF(N13="Y",100,0)+IF(O13="Y",10,0)+(C13-2019)/10,"") | Q13: =IF(P13="","",RANK(P13,$P$2:$P$45)) | S13: =IF(I13="","Pending",IF(I13="Exclude","Excluded at title/abstract",IF(V13="Y","Excluded: eligible by abstract, not assessed (E9)",IF(K13="","Pending full text",IF(K13="Exclude","Excluded at full text",IF(K13="Not retrieved","Not retrieved",IF(R13="Yes","Included",IF(R13="No","Excluded: eligible, not selected (E9)","Eligible - pending selection")))))))) -> Excluded at title/abstract | T13: Y
A14: 13 | B14: Xiong C. | C14: 2025 | D14: DelphiAgent: A trustworthy multi-agent verification framework for automated fact verification | E14: Information Processing and Management | F14: 10.1016/j.ipm.2025.104241 | G14: English | H14: Large Language Models (LLMs) have been investigated for many reasoning-intensive tasks including fact verification and exhibited outstanding performance via coupling LLM's internal and external knowledge. However, non-agentic LLM-based methods produce responses based on direct prompts in an one-off manner, suffering from challenges in factuality and hallucinations. In this paper, we propose DelphiAgent, an innovative agentic framework for trustworthy fact-checking that employs multiple LLMs to emulate the workflow of the Delphi method, aiming at enhancing transparency in the decision-making procedure and mitigating hallucinations when generating justifications. This is implemented through a duel-system framework that integrates the evidence mining module and the Delphi decision-making module. The evidence mining module extracts evidence from raw uncensored reports and refines evidence, ensuring the provision of instructive rationales for the subsequent module. Meanwhile, drawing inspiration from the Delphi method, the decision-making module devises multiple LLM-based agents with distinct personalities to make factuality judgments individually based on the claim and its verified evidence, and reaches a consensus through multiple rounds of feedback and synthesis. The experimental findings from two challenging datasets indicate that DelphiAgent not only surpasses current LLM-based approaches but also is on par with state-of-the-art LLM-enhanced supervised baselines without necessitating a training regime, with macF1 improvements reaching up to 6.84% on RAWFC and comparable performance on LIAR-RAW. Furthermore, the generated justifications throughout the workflow underscore the trustworthiness of our proposed framework. The official implementation of this paper is available at https://github.com/zjfgh2015/DelphiAgent. © 2025 Elsevier Ltd | I14: Include | P14: =IF(K14="Eligible",IF(M14=1,1000,0)+IF(N14="Y",100,0)+IF(O14="Y",10,0)+(C14-2019)/10,"") | Q14: =IF(P14="","",RANK(P14,$P$2:$P$45)) | S14: =IF(I14="","Pending",IF(I14="Exclude","Excluded at title/abstract",IF(V14="Y","Excluded: eligible by abstract, not assessed (E9)",IF(K14="","Pending full text",IF(K14="Exclude","Excluded at full text",IF(K14="Not retrieved","Not retrieved",IF(R14="Yes","Included",IF(R14="No","Excluded: eligible, not selected (E9)","Eligible - pending selection")))))))) -> Pending full text
A15: 14 | B15: Kalian A.D. | C15: 2025 | D15: From LLMs to sustainable proteins: fine-tuning and prompt engineering for multi-agent AI in waste carbon-utilising microbial protein production | E15: Carbon Capture Science and Technology | F15: 10.1016/j.ccst.2025.100525 | G15: English | H15: The global demand for sustainable protein sources has accelerated the need for intelligent tools that can rapidly process and synthesise domain-specific scientific knowledge. In this study, we present a multi-agent Artificial Intelligence (AI) framework designed to support sustainable protein production research, with an initial focus on microbial protein fermentation using side-streams which enables waste carbon capture and utilisation (CCU). Our Retrieval-Augmented Generation (RAG)-oriented system consists of two GPT-based LLM agents: (1) a literature search agent that retrieves relevant scientific literature on microbial protein production for a specified microbial strain, and (2) an information extraction agent that processes the retrieved content to extract relevant biological and chemical information. Two parallel methodologies, fine-tuning and prompt engineering, were explored for agent optimisation. Both methods demonstrated effectiveness at improving the performance of the information extraction agent in terms of transformer-based cosine similarity scores between obtained and ideal outputs. Mean cosine similarity scores were increased by up to 25 %, while universally reaching mean scores of ≥0.89 against ideal output text. Fine-tuning overall improved the mean scores to a greater extent (consistently of ≥0.94) compared to prompt engineering, although lower statistical uncertainties were observed with the latter approach. A user interface was developed and published for enabling the use of the multi-agent AI system, alongside preliminary exploration of additional chemical safety-based search capabilities relevant to CCU-integrated sustainable protein production. © 2025 The Author(s). Published by Elsevier Ltd on behalf of Institution of Chemical Engineers (IChemE). This is an open access article under the CC BY license. http://creativecommons.org/licenses/by/4.0/ | I15: Include | P15: =IF(K15="Eligible",IF(M15=1,1000,0)+IF(N15="Y",100,0)+IF(O15="Y",10,0)+(C15-2019)/10,"") | Q15: =IF(P15="","",RANK(P15,$P$2:$P$45)) | S15: =IF(I15="","Pending",IF(I15="Exclude","Excluded at title/abstract",IF(V15="Y","Excluded: eligible by abstract, not assessed (E9)",IF(K15="","Pending full text",IF(K15="Exclude","Excluded at full text",IF(K15="Not retrieved","Not retrieved",IF(R15="Yes","Included",IF(R15="No","Excluded: eligible, not selected (E9)","Eligible - pending selection")))))))) -> Pending full text
A16: 15 | B16: Nguyen T.-A. | C16: 2026 | D16: Debating to verify: A robust and explainable multi-agent LLM system for fact-checking | E16: ICT Express | F16: 10.1016/j.icte.2026.05.017 | G16: English | H16: Large language models have advanced automated fact verification, yet single-agent prompting remains prone to hallucination, while fine-tuned models suffer from limited scalability and cross-domain generalization. This paper proposes FC-MAD, a training-free multi-agent debate framework that coordinates multiple LLMs through structured critique, context summarization, and judge-guided consensus reasoning. Extensive experiments on Vietnamese (ViFactCheck), multilingual (X-Fact), and English (FEVER) benchmarks show that FC-MAD consistently outperforms strong fine-tuned and prompting-based baselines, achieving state-of-the-art performance on ViFactCheck and FEVER, while delivering robust gains across X-Fact languages. These results highlight the effectiveness of structured multi-agent reasoning for reliable AI-based fact-checking systems. © 2026 The Author(s). | I16: Include | P16: =IF(K16="Eligible",IF(M16=1,1000,0)+IF(N16="Y",100,0)+IF(O16="Y",10,0)+(C16-2019)/10,"") | Q16: =IF(P16="","",RANK(P16,$P$2:$P$45)) | S16: =IF(I16="","Pending",IF(I16="Exclude","Excluded at title/abstract",IF(V16="Y","Excluded: eligible by abstract, not assessed (E9)",IF(K16="","Pending full text",IF(K16="Exclude","Excluded at full text",IF(K16="Not retrieved","Not retrieved",IF(R16="Yes","Included",IF(R16="No","Excluded: eligible, not selected (E9)","Eligible - pending selection")))))))) -> Pending full text
A17: 16 | B17: Lu J. | C17: 2025 | D17: Automated building energy modeling for energy retrofits using a large language model-based multi-agent framework | E17: iScience | F17: 10.1016/j.isci.2025.113867 | G17: English | H17: Building energy modeling is critical for retrofit design, but it is labor-intensive. We present Data2BEM (Data to Building Energy Model), a large language model-based multi-agent framework that parses architectural drawings, specifications, and sensor data to automatically generate and calibrate building energy simulations. Applied to an existing University of Cambridge office building, Data2BEM produced a calibrated model meeting industry accuracy benchmarks and enabled the assessment of heat-electrification retrofits. Relative to professional practice, the system reduced total modeling time by over 90% (48 min versus 8–32 h) with minimal human input. The workflow integrates information extraction, model generation, and data-driven calibration, delivering end-to-end automation while accurately reflecting measured performance. These results indicate that large language model-driven multi-agent methods can accelerate retrofit analysis, lowering expertise and time barriers for practitioners and supporting scalable pathways to building-sector decarbonization. © 2025 The Authors | I17: Exclude | J17: E5 | P17: =IF(K17="Eligible",IF(M17=1,1000,0)+IF(N17="Y",100,0)+IF(O17="Y",10,0)+(C17-2019)/10,"") | Q17: =IF(P17="","",RANK(P17,$P$2:$P$45)) | S17: =IF(I17="","Pending",IF(I17="Exclude","Excluded at title/abstract",IF(V17="Y","Excluded: eligible by abstract, not assessed (E9)",IF(K17="","Pending full text",IF(K17="Exclude","Excluded at full text",IF(K17="Not retrieved","Not retrieved",IF(R17="Yes","Included",IF(R17="No","Excluded: eligible, not selected (E9)","Eligible - pending selection")))))))) -> Excluded at title/abstract
A18: 17 | B18: Vo T. | C18: 2026 | D18: Unsupervised column relevance extraction for table-based fact verification via structured and explainable large language model reasoning | E18: Computers and Electrical Engineering | F18: 10.1016/j.compeleceng.2026.111473 | G18: English | H18: Recent advances in large language models have driven remarkable progress in automated reasoning over structured tabular data, with applications spanning healthcare, scientific research, and public policy. Despite significant advancements, state-of-the-art methods face some challenges: they often require complex multi-agent or tool-based pipelines, fine-tuning on domain-specific data, or dependence on closed-source commercial models, which can limit accessibility, reproducibility, and transparency. To overcome these limitations, we introduce UCRET, a modular and fully interpretable framework for zero-shot table-based fact verification. UCRET combines open-source large language models with explicit, step-by-step explanations for each possible verification outcome, avoiding both task-specific fine-tuning and reliance on proprietary models. Its key novelty lies in applying spherical k -means to unsupervised, claim-driven column selection , which identifies the most relevant evidence columns before reasoning and reduces the amount of irrelevant tabular information passed to the reasoning stage. Given this reduced table, the model elicits counterfactual explanations for each veracity label and aggregates them into a final decision. This design both clarifies why a label is predicted and limits token usage by focusing the model on salient columns. Empirical results on medical, scientific, and general-domain Wikipedia benchmarks demonstrate that our framework achieves competitive performance while maintaining transparency throughout. Ablations confirm that both the spherical k-means column selector and the counterfactual explanation stage are necessary to achieve the observed accuracy and transparency. © 2026 Elsevier Ltd. | I18: Exclude | J18: E4 | P18: =IF(K18="Eligible",IF(M18=1,1000,0)+IF(N18="Y",100,0)+IF(O18="Y",10,0)+(C18-2019)/10,"") | Q18: =IF(P18="","",RANK(P18,$P$2:$P$45)) | S18: =IF(I18="","Pending",IF(I18="Exclude","Excluded at title/abstract",IF(V18="Y","Excluded: eligible by abstract, not assessed (E9)",IF(K18="","Pending full text",IF(K18="Exclude","Excluded at full text",IF(K18="Not retrieved","Not retrieved",IF(R18="Yes","Included",IF(R18="No","Excluded: eligible, not selected (E9)","Eligible - pending selection")))))))) -> Excluded at title/abstract
A19: 18 | B19: Nagpal R. | C19: 2026 | D19: Mitigating Hallucinations in Finance-Based Multi-Agent Large Language Model Systems | E19: Electronics (Switzerland) | F19: 10.3390/electronics15194456 | G19: English | H19: Large language models are increasingly used for financial question answering, while they are prone to generating hallucinated content. In this research, we propose a multi-signal framework for hallucination detection and mitigation. Our framework combines six signals (entailment, semantic similarity, claim verification, numeric consistency, token overlap and confidence calibration techniques) to identify hallucination type and severity. We evaluated our framework using multiple language models across three financial QA benchmark datasets (FinQA, FinanceQA, and FinDER). Our proposed framework corrects up to 78.4% of the detected hallucinations (fix rate on the hallucinated subset of FinQA; 47.7% on FinanceQA and 45.7% on FinDER), outperforming a type-agnostic mitigation baseline on all three datasets. This highlights that targeted, type-aware hallucination mitigation can significantly improve answer reliability while remaining computationally effective. © 2026 by the authors. | I19: Exclude | J19: E4 | P19: =IF(K19="Eligible",IF(M19=1,1000,0)+IF(N19="Y",100,0)+IF(O19="Y",10,0)+(C19-2019)/10,"") | Q19: =IF(P19="","",RANK(P19,$P$2:$P$45)) | S19: =IF(I19="","Pending",IF(I19="Exclude","Excluded at title/abstract",IF(V19="Y","Excluded: eligible by abstract, not assessed (E9)",IF(K19="","Pending full text",IF(K19="Exclude","Excluded at full text",IF(K19="Not retrieved","Not retrieved",IF(R19="Yes","Included",IF(R19="No","Excluded: eligible, not selected (E9)","Eligible - pending selection")))))))) -> Excluded at title/abstract | T19: Y
A20: 19 | B20: Quelle D. | C20: 2024 | D20: The perils and promises of fact-checking with large language models | E20: Frontiers in Artificial Intelligence | F20: 10.3389/frai.2024.1341697 | G20: English | H20: Automated fact-checking, using machine learning to verify claims, has grown vital as misinformation spreads beyond human fact-checking capacity. Large language models (LLMs) like GPT-4 are increasingly trusted to write academic papers, lawsuits, and news articles and to verify information, emphasizing their role in discerning truth from falsehood and the importance of being able to verify their outputs. Understanding the capacities and limitations of LLMs in fact-checking tasks is therefore essential for ensuring the health of our information ecosystem. Here, we evaluate the use of LLM agents in fact-checking by having them phrase queries, retrieve contextual data, and make decisions. Importantly, in our framework, agents explain their reasoning and cite the relevant sources from the retrieved context. Our results show the enhanced prowess of LLMs when equipped with contextual information. GPT-4 outperforms GPT-3, but accuracy varies based on query language and claim veracity. While LLMs show promise in fact-checking, caution is essential due to inconsistent accuracy. Our investigation calls for further research, fostering a deeper comprehension of when agents succeed and when they fail. Copyright © 2024 Quelle and Bovet. | I20: Maybe | P20: =IF(K20="Eligible",IF(M20=1,1000,0)+IF(N20="Y",100,0)+IF(O20="Y",10,0)+(C20-2019)/10,"") | Q20: =IF(P20="","",RANK(P20,$P$2:$P$45)) | S20: =IF(I20="","Pending",IF(I20="Exclude","Excluded at title/abstract",IF(V20="Y","Excluded: eligible by abstract, not assessed (E9)",IF(K20="","Pending full text",IF(K20="Exclude","Excluded at full text",IF(K20="Not retrieved","Not retrieved",IF(R20="Yes","Included",IF(R20="No","Excluded: eligible, not selected (E9)","Eligible - pending selection")))))))) -> Pending full text
A21: 20 | B21: Alrayzah A. | C21: 2025 | D21: CoAgt: unleashing the reasoning capabilities of large language models on tabular data with a chain of agents | E21: PeerJ Computer Science | F21: 10.7717/peerj-cs.3423 | G21: English | H21: Large language models (LLMs) have shown remarkable progress in text-based reasoning, but they continue to struggle with large and complex tables. Token limitations and the loss of structural dependencies make it difficult for a single model to extract evidence, connect relationships, and produce reliable answers. To address this challenge, we introduce Chain of Agents (CoAgt) a multi-agent framework inspired by how human reason with tables, scanning data, comparing values, retaining information, and making decisions. In CoAgt, different agents share the workload: Collectors gather evidence from subtables, the Synthesizer integrates their findings into a coherent answer, and the Refiner ensures clarity and correctness. This division of labor makes the reasoning process both scalable and interpretable, while reducing the risk of errors that often occur when one model handles all steps alone. We evaluate CoAgt on two widely used benchmarks. On WikiTableQuestions (WikiTQ) it achieves 85.4% accuracy, outperforming the strong Chain-of-Table baseline by more than twenty-five percentage points. On Table Fact-Checking (TabFact) it reaches 96.6% accuracy, exceeding previous state-of-the-art results. These findings show that breaking reasoning into specialized agents not only improves performance but also offers a transparent and reliable approach for reasoning over large, complex tables. Copyright 2025 Alrayzah and Alqhtani. Distributed under Creative Commons CC-BY 4.0. http://www.creativecommons.org/licenses/by/4.0/ | I21: Exclude | J21: E6 | P21: =IF(K21="Eligible",IF(M21=1,1000,0)+IF(N21="Y",100,0)+IF(O21="Y",10,0)+(C21-2019)/10,"") | Q21: =IF(P21="","",RANK(P21,$P$2:$P$45)) | S21: =IF(I21="","Pending",IF(I21="Exclude","Excluded at title/abstract",IF(V21="Y","Excluded: eligible by abstract, not assessed (E9)",IF(K21="","Pending full text",IF(K21="Exclude","Excluded at full text",IF(K21="Not retrieved","Not retrieved",IF(R21="Yes","Included",IF(R21="No","Excluded: eligible, not selected (E9)","Eligible - pending selection")))))))) -> Excluded at title/abstract | T21: Y
A22: 21 | B22: Ghosh S. | C22: 2026 | D22: LLM-based AI agents for automated extraction of material properties and structural features | E22: Computational Materials Science | F22: 10.1016/j.commatsci.2026.114521 | G22: English | H22: The lack of large, machine-readable datasets continues to constrain data-driven materials discovery. We present a closed-loop, agentic large-language-model (LLM) workflow that autonomously extracts thermoelectric and structural properties from ∼ 10,000 full-text scientific articles. The framework integrates context-engineered multi-agent orchestration , dynamic token allocation , and a built-in LLM-Judge that performs schema-level consistency checks to suppress hallucinated or malformed outputs. Unlike prior systems restricted to narrative text, our workflow unifies text, tables, and captions under a single reasoning graph, enabling cross-modal extraction and automated validation of tabular data. Benchmarking on a manually curated set of 50 papers shows that GPT-4.1 achieves the highest extraction accuracy (F1≈0.91 for thermoelectric properties, F1≈0.838 for structural fields). At the same time, GPT-4.1 Mini offers nearly comparable performance (F1≈0.889 for thermoelectric, F1≈0.833 for structural) at a fraction of the cost, enabling large-scale deployment. Applying this workflow, we create a data set of 18,869 property temperature records with normalized units, spanning the figure of merit (ZT), Seebeck coefficient, electrical conductivity, power factor, and thermal conductivity, together with structural attributes such as crystal class, space group, and doping strategy. Following chemical validation, 11,927 entries are released through an interactive web explorer supporting semantic filters, numeric queries, and CSV export. Beyond thermoelectrics, this cross-modal, extensible agent architecture establishes a general paradigm for large-scale, verifiable data extraction from unstructured scientific literature. © 2026 Elsevier B.V. | I22: Include | P22: =IF(K22="Eligible",IF(M22=1,1000,0)+IF(N22="Y",100,0)+IF(O22="Y",10,0)+(C22-2019)/10,"") | Q22: =IF(P22="","",RANK(P22,$P$2:$P$45)) | S22: =IF(I22="","Pending",IF(I22="Exclude","Excluded at title/abstract",IF(V22="Y","Excluded: eligible by abstract, not assessed (E9)",IF(K22="","Pending full text",IF(K22="Exclude","Excluded at full text",IF(K22="Not retrieved","Not retrieved",IF(R22="Yes","Included",IF(R22="No","Excluded: eligible, not selected (E9)","Eligible - pending selection")))))))) -> Pending full text
A23: 22 | B23: Zhang L. | C23: 2025 | D23: Automatic building energy model development and debugging using large language models agentic workflow | E23: Energy and Buildings | F23: 10.1016/j.enbuild.2024.115116 | G23: English | H23: Building energy modeling (BEM) is a complex process that demands significant time and expertise, limiting its broader application in building design and operations. While Large Language Models (LLMs) agentic workflow have facilitated complex engineering processes, their application in BEM has not been specifically explored. This paper investigates the feasibility of automating BEM using LLM agentic workflow. We developed a generic LLM-planning-based workflow that takes a building description as input and generates an error-free EnergyPlus building energy model. Our robust workflow includes four core agents: 1) Building Description Pre-Processing, 2) IDF Object Information Extraction, 3) Single IDF Object Generator Suite, and 4) IDF Debugging Agent. These agents divide the complex tasks into manageable sub-steps, enabling LLMs to generate accurate and reliable results at each stage. The case study demonstrates the successful translation of a building description into an error-free EnergyPlus model for the iUnit modular building at the National Renewable Energy Laboratory. The effectiveness of our workflow surpasses: 1) naive prompt engineering, 2) other LLM-based workflows, and 3) manual modeling, in terms of accuracy, reliability, and time efficiency. The paper concludes with a discussion on the interplay between foundational models and LLM agent planning design, advocating for the use of fine-tuned, specialized models to advance this field. © 2024 Elsevier B.V. | I23: Exclude | J23: E5 | P23: =IF(K23="Eligible",IF(M23=1,1000,0)+IF(N23="Y",100,0)+IF(O23="Y",10,0)+(C23-2019)/10,"") | Q23: =IF(P23="","",RANK(P23,$P$2:$P$45)) | S23: =IF(I23="","Pending",IF(I23="Exclude","Excluded at title/abstract",IF(V23="Y","Excluded: eligible by abstract, not assessed (E9)",IF(K23="","Pending full text",IF(K23="Exclude","Excluded at full text",IF(K23="Not retrieved","Not retrieved",IF(R23="Yes","Included",IF(R23="No","Excluded: eligible, not selected (E9)","Eligible - pending selection")))))))) -> Excluded at title/abstract
